Traceback (most recent call last):
  File "/opt/hostedtoolcache/Python/3.8.13/x64/lib/python3.8/site-packages/jupyter_cache/executors/utils.py", line 51, in single_nb_execution
    executenb(
  File "/opt/hostedtoolcache/Python/3.8.13/x64/lib/python3.8/site-packages/nbclient/client.py", line 1204, in execute
    return NotebookClient(nb=nb, resources=resources, km=km, **kwargs).execute()
  File "/opt/hostedtoolcache/Python/3.8.13/x64/lib/python3.8/site-packages/nbclient/util.py", line 84, in wrapped
    return just_run(coro(*args, **kwargs))
  File "/opt/hostedtoolcache/Python/3.8.13/x64/lib/python3.8/site-packages/nbclient/util.py", line 62, in just_run
    return loop.run_until_complete(coro)
  File "/opt/hostedtoolcache/Python/3.8.13/x64/lib/python3.8/asyncio/base_events.py", line 616, in run_until_complete
    return future.result()
  File "/opt/hostedtoolcache/Python/3.8.13/x64/lib/python3.8/site-packages/nbclient/client.py", line 663, in async_execute
    await self.async_execute_cell(
  File "/opt/hostedtoolcache/Python/3.8.13/x64/lib/python3.8/site-packages/nbclient/client.py", line 965, in async_execute_cell
    await self._check_raise_for_error(cell, cell_index, exec_reply)
  File "/opt/hostedtoolcache/Python/3.8.13/x64/lib/python3.8/site-packages/nbclient/client.py", line 862, in _check_raise_for_error
    raise CellExecutionError.from_cell_and_msg(cell, exec_reply_content)
nbclient.exceptions.CellExecutionError: An error occurred while executing the following cell:
------------------
# install.packages("librarian", quiet = T)
librarian::shelf(tidyverse, lmtest, sandwich, broom, hdm, quiet = T)
## loading the data
Penn <- as_tibble(read.table("https://github.com/d2cml-ai/14.388_r/raw/main/Data/penn_jae.dat", header=T ))
n <- dim(Penn)[1]
p_1 <- dim(Penn)[2]
Penn <- filter(Penn, tg == 4 | tg == 0)# subset(Penn, tg==4 | tg==0)
attach(Penn)
------------------

Error in file(file, "rt"): cannot open the connection to 'https://github.com/d2cml-ai/14.388_r/raw/main/Data/penn_jae.dat'
Traceback:

1. as_tibble(read.table("https://github.com/d2cml-ai/14.388_r/raw/main/Data/penn_jae.dat", 
 .     header = T))
2. read.table("https://github.com/d2cml-ai/14.388_r/raw/main/Data/penn_jae.dat", 
 .     header = T)
3. file(file, "rt")
ERROR: Error in file(file, "rt"): cannot open the connection to 'https://github.com/d2cml-ai/14.388_r/raw/main/Data/penn_jae.dat'


