Traceback (most recent call last):
  File "/opt/hostedtoolcache/Python/3.8.13/x64/lib/python3.8/site-packages/jupyter_cache/executors/utils.py", line 51, in single_nb_execution
    executenb(
  File "/opt/hostedtoolcache/Python/3.8.13/x64/lib/python3.8/site-packages/nbclient/client.py", line 1204, in execute
    return NotebookClient(nb=nb, resources=resources, km=km, **kwargs).execute()
  File "/opt/hostedtoolcache/Python/3.8.13/x64/lib/python3.8/site-packages/nbclient/util.py", line 84, in wrapped
    return just_run(coro(*args, **kwargs))
  File "/opt/hostedtoolcache/Python/3.8.13/x64/lib/python3.8/site-packages/nbclient/util.py", line 62, in just_run
    return loop.run_until_complete(coro)
  File "/opt/hostedtoolcache/Python/3.8.13/x64/lib/python3.8/asyncio/base_events.py", line 616, in run_until_complete
    return future.result()
  File "/opt/hostedtoolcache/Python/3.8.13/x64/lib/python3.8/site-packages/nbclient/client.py", line 663, in async_execute
    await self.async_execute_cell(
  File "/opt/hostedtoolcache/Python/3.8.13/x64/lib/python3.8/site-packages/nbclient/client.py", line 965, in async_execute_cell
    await self._check_raise_for_error(cell, cell_index, exec_reply)
  File "/opt/hostedtoolcache/Python/3.8.13/x64/lib/python3.8/site-packages/nbclient/client.py", line 862, in _check_raise_for_error
    raise CellExecutionError.from_cell_and_msg(cell, exec_reply_content)
nbclient.exceptions.CellExecutionError: An error occurred while executing the following cell:
------------------
install.packages("librarian", quiet = T)
librarian::shelf(keras, tidyverse)
data = read_csv("https://raw.githubusercontent.com/d2cml-ai/14.388_R/main/Data/wage2015_subsample_inference.csv", show_col_types = F)
Z <- data |> select(-c(lwage, wage)) # regressors
------------------

Error in open.connection(structure(4L, class = c("curl", "connection"), conn_id = <pointer: 0x52c>), : HTTP error 404.
Traceback:

1. read_csv("https://raw.githubusercontent.com/d2cml-ai/14.388_R/main/Data/wage2015_subsample_inference.csv", 
 .     show_col_types = F)
2. vroom::vroom(file, delim = ",", col_names = col_names, col_types = col_types, 
 .     col_select = {
 .         {
 .             col_select
 .         }
 .     }, id = id, .name_repair = name_repair, skip = skip, n_max = n_max, 
 .     na = na, quote = quote, comment = comment, skip_empty_rows = skip_empty_rows, 
 .     trim_ws = trim_ws, escape_double = TRUE, escape_backslash = FALSE, 
 .     locale = locale, guess_max = guess_max, show_col_types = show_col_types, 
 .     progress = progress, altrep = lazy, num_threads = num_threads)
3. vroom_(file, delim = delim %||% col_types$delim, col_names = col_names, 
 .     col_types = col_types, id = id, skip = skip, col_select = col_select, 
 .     name_repair = .name_repair, na = na, quote = quote, trim_ws = trim_ws, 
 .     escape_double = escape_double, escape_backslash = escape_backslash, 
 .     comment = comment, skip_empty_rows = skip_empty_rows, locale = locale, 
 .     guess_max = guess_max, n_max = n_max, altrep = vroom_altrep(altrep), 
 .     num_threads = num_threads, progress = progress)
4. (function (con, ...) 
 . UseMethod("open"))(structure(4L, class = c("curl", "connection"
 . ), conn_id = <pointer: 0x52c>), "rb")
5. open.connection(structure(4L, class = c("curl", "connection"), conn_id = <pointer: 0x52c>), 
 .     "rb")
ERROR: Error in open.connection(structure(4L, class = c("curl", "connection"), conn_id = <pointer: 0x52c>), : HTTP error 404.


